INFO:2020-02-22 22:07:36,532:_internal.py:_log: * Running on http://0.0.0.0:5001/ (Press CTRL+C to quit)
INFO:2020-02-22 22:11:16,019:_internal.py:_log:127.0.0.1 - - [22/Feb/2020 22:11:16] "POST /init HTTP/1.1" 400 -
INFO:2020-02-22 22:11:40,161:_internal.py:_log:127.0.0.1 - - [22/Feb/2020 22:11:40] "POST /init HTTP/1.1" 400 -
INFO:2020-02-22 22:14:51,117:_internal.py:_log: * Running on http://0.0.0.0:5001/ (Press CTRL+C to quit)
INFO:2020-02-22 22:15:30,357:workflow_proxy.py:init:parameters are initialized.
ERROR:2020-02-22 22:15:32,550:app.py:log_exception:Exception on /init [POST]
Traceback (most recent call last):
  File "D:\soft\2019-12-03-python\lib\site-packages\flask\app.py", line 2446, in wsgi_app
    response = self.full_dispatch_request()
  File "D:\soft\2019-12-03-python\lib\site-packages\flask\app.py", line 1952, in full_dispatch_request
    return self.finalize_request(rv)
  File "D:\soft\2019-12-03-python\lib\site-packages\flask\app.py", line 1967, in finalize_request
    response = self.make_response(rv)
  File "D:\soft\2019-12-03-python\lib\site-packages\flask\app.py", line 2097, in make_response
    "The view function did not return a valid response. The"
TypeError: The view function did not return a valid response. The function either returned None or ended without a return statement.
INFO:2020-02-22 22:15:32,621:_internal.py:_log:127.0.0.1 - - [22/Feb/2020 22:15:32] "POST /init HTTP/1.1" 500 -
INFO:2020-02-22 22:15:50,686:_internal.py:_log: * Running on http://0.0.0.0:5001/ (Press CTRL+C to quit)
INFO:2020-02-22 22:16:08,906:workflow_proxy.py:init:parameters are initialized.
ERROR:2020-02-22 22:16:13,216:app.py:log_exception:Exception on /init [POST]
Traceback (most recent call last):
  File "D:\soft\2019-12-03-python\lib\site-packages\flask\app.py", line 2446, in wsgi_app
    response = self.full_dispatch_request()
  File "D:\soft\2019-12-03-python\lib\site-packages\flask\app.py", line 1952, in full_dispatch_request
    return self.finalize_request(rv)
  File "D:\soft\2019-12-03-python\lib\site-packages\flask\app.py", line 1967, in finalize_request
    response = self.make_response(rv)
  File "D:\soft\2019-12-03-python\lib\site-packages\flask\app.py", line 2097, in make_response
    "The view function did not return a valid response. The"
TypeError: The view function did not return a valid response. The function either returned None or ended without a return statement.
INFO:2020-02-22 22:16:13,219:_internal.py:_log:127.0.0.1 - - [22/Feb/2020 22:16:13] "POST /init HTTP/1.1" 500 -
INFO:2020-02-22 22:17:21,941:workflow_proxy.py:executetask:Task is run
INFO:2020-02-22 22:18:33,921:_internal.py:_log: * Running on http://0.0.0.0:5001/ (Press CTRL+C to quit)
INFO:2020-02-22 22:18:45,147:workflow_proxy.py:init:parameters are initialized.
ERROR:2020-02-22 22:18:45,148:app.py:log_exception:Exception on /init [POST]
Traceback (most recent call last):
  File "D:\soft\2019-12-03-python\lib\site-packages\flask\app.py", line 2446, in wsgi_app
    response = self.full_dispatch_request()
  File "D:\soft\2019-12-03-python\lib\site-packages\flask\app.py", line 1952, in full_dispatch_request
    return self.finalize_request(rv)
  File "D:\soft\2019-12-03-python\lib\site-packages\flask\app.py", line 1967, in finalize_request
    response = self.make_response(rv)
  File "D:\soft\2019-12-03-python\lib\site-packages\flask\app.py", line 2097, in make_response
    "The view function did not return a valid response. The"
TypeError: The view function did not return a valid response. The function either returned None or ended without a return statement.
INFO:2020-02-22 22:18:45,152:_internal.py:_log:127.0.0.1 - - [22/Feb/2020 22:18:45] "POST /init HTTP/1.1" 500 -
INFO:2020-02-22 22:19:01,378:workflow_proxy.py:executetask:Task is run
INFO:2020-02-22 22:19:23,711:_internal.py:_log: * Running on http://0.0.0.0:5001/ (Press CTRL+C to quit)
INFO:2020-02-22 22:19:31,762:workflow_proxy.py:init:parameters are initialized.
ERROR:2020-02-22 22:19:31,764:app.py:log_exception:Exception on /init [POST]
Traceback (most recent call last):
  File "D:\soft\2019-12-03-python\lib\site-packages\flask\app.py", line 2446, in wsgi_app
    response = self.full_dispatch_request()
  File "D:\soft\2019-12-03-python\lib\site-packages\flask\app.py", line 1952, in full_dispatch_request
    return self.finalize_request(rv)
  File "D:\soft\2019-12-03-python\lib\site-packages\flask\app.py", line 1967, in finalize_request
    response = self.make_response(rv)
  File "D:\soft\2019-12-03-python\lib\site-packages\flask\app.py", line 2097, in make_response
    "The view function did not return a valid response. The"
TypeError: The view function did not return a valid response. The function either returned None or ended without a return statement.
INFO:2020-02-22 22:19:31,769:_internal.py:_log:127.0.0.1 - - [22/Feb/2020 22:19:31] "POST /init HTTP/1.1" 500 -
INFO:2020-02-22 22:19:42,866:workflow_proxy.py:executetask:Task is run
ERROR:2020-02-22 22:19:42,909:app.py:log_exception:Exception on /run [POST]
Traceback (most recent call last):
  File "D:\soft\2019-12-03-python\lib\site-packages\flask\app.py", line 2446, in wsgi_app
    response = self.full_dispatch_request()
  File "D:\soft\2019-12-03-python\lib\site-packages\flask\app.py", line 1951, in full_dispatch_request
    rv = self.handle_user_exception(e)
  File "D:\soft\2019-12-03-python\lib\site-packages\flask\app.py", line 1820, in handle_user_exception
    reraise(exc_type, exc_value, tb)
  File "D:\soft\2019-12-03-python\lib\site-packages\flask\_compat.py", line 39, in reraise
    raise value
  File "D:\soft\2019-12-03-python\lib\site-packages\flask\app.py", line 1949, in full_dispatch_request
    rv = self.dispatch_request()
  File "D:\soft\2019-12-03-python\lib\site-packages\flask\app.py", line 1935, in dispatch_request
    return self.view_functions[rule.endpoint](**req.view_args)
  File "D:/code/fudan/python/cpss-process/service/workflow_proxy.py", line 70, in executetask
    params = get_params()
  File "D:/code/fudan/python/cpss-process/service/workflow_proxy.py", line 121, in get_params
    input_resource_param_name = input0.split('.')[1]
IndexError: list index out of range
INFO:2020-02-22 22:19:42,930:_internal.py:_log:127.0.0.1 - - [22/Feb/2020 22:19:42] "POST /run HTTP/1.1" 500 -
INFO:2020-02-22 22:19:47,724:workflow_proxy.py:init:parameters are initialized.
ERROR:2020-02-22 22:19:47,725:app.py:log_exception:Exception on /init [POST]
Traceback (most recent call last):
  File "D:\soft\2019-12-03-python\lib\site-packages\flask\app.py", line 2446, in wsgi_app
    response = self.full_dispatch_request()
  File "D:\soft\2019-12-03-python\lib\site-packages\flask\app.py", line 1952, in full_dispatch_request
    return self.finalize_request(rv)
  File "D:\soft\2019-12-03-python\lib\site-packages\flask\app.py", line 1967, in finalize_request
    response = self.make_response(rv)
  File "D:\soft\2019-12-03-python\lib\site-packages\flask\app.py", line 2097, in make_response
    "The view function did not return a valid response. The"
TypeError: The view function did not return a valid response. The function either returned None or ended without a return statement.
INFO:2020-02-22 22:19:47,729:_internal.py:_log:127.0.0.1 - - [22/Feb/2020 22:19:47] "POST /init HTTP/1.1" 500 -
INFO:2020-02-22 22:20:24,472:_internal.py:_log: * Running on http://0.0.0.0:5001/ (Press CTRL+C to quit)
INFO:2020-02-22 22:20:28,784:workflow_proxy.py:init:parameters are initialized.
INFO:2020-02-22 22:20:28,787:_internal.py:_log:127.0.0.1 - - [22/Feb/2020 22:20:28] "POST /init HTTP/1.1" 200 -
INFO:2020-02-22 22:20:45,354:workflow_proxy.py:executetask:Task is run
ERROR:2020-02-22 22:21:11,476:app.py:log_exception:Exception on /run [POST]
Traceback (most recent call last):
  File "D:\soft\2019-12-03-python\lib\site-packages\flask\app.py", line 2446, in wsgi_app
    response = self.full_dispatch_request()
  File "D:\soft\2019-12-03-python\lib\site-packages\flask\app.py", line 1951, in full_dispatch_request
    rv = self.handle_user_exception(e)
  File "D:\soft\2019-12-03-python\lib\site-packages\flask\app.py", line 1820, in handle_user_exception
    reraise(exc_type, exc_value, tb)
  File "D:\soft\2019-12-03-python\lib\site-packages\flask\_compat.py", line 39, in reraise
    raise value
  File "D:\soft\2019-12-03-python\lib\site-packages\flask\app.py", line 1949, in full_dispatch_request
    rv = self.dispatch_request()
  File "D:\soft\2019-12-03-python\lib\site-packages\flask\app.py", line 1935, in dispatch_request
    return self.view_functions[rule.endpoint](**req.view_args)
  File "D:/code/fudan/python/cpss-process/service/workflow_proxy.py", line 71, in executetask
    params = get_params()
  File "D:/code/fudan/python/cpss-process/service/workflow_proxy.py", line 124, in get_params
    input_resource_param_name = input0.split('.')[1]
IndexError: list index out of range
INFO:2020-02-22 22:21:11,487:_internal.py:_log:127.0.0.1 - - [22/Feb/2020 22:21:11] "POST /run HTTP/1.1" 500 -
INFO:2020-02-22 22:21:38,369:workflow_proxy.py:executetask:Task is run
INFO:2020-02-22 22:23:04,085:_internal.py:_log: * Running on http://0.0.0.0:5001/ (Press CTRL+C to quit)
INFO:2020-02-22 22:23:13,714:workflow_proxy.py:executetask:Task is run
ERROR:2020-02-22 22:23:13,721:app.py:log_exception:Exception on /run [POST]
Traceback (most recent call last):
  File "D:\soft\2019-12-03-python\lib\site-packages\flask\app.py", line 2446, in wsgi_app
    response = self.full_dispatch_request()
  File "D:\soft\2019-12-03-python\lib\site-packages\flask\app.py", line 1951, in full_dispatch_request
    rv = self.handle_user_exception(e)
  File "D:\soft\2019-12-03-python\lib\site-packages\flask\app.py", line 1820, in handle_user_exception
    reraise(exc_type, exc_value, tb)
  File "D:\soft\2019-12-03-python\lib\site-packages\flask\_compat.py", line 39, in reraise
    raise value
  File "D:\soft\2019-12-03-python\lib\site-packages\flask\app.py", line 1949, in full_dispatch_request
    rv = self.dispatch_request()
  File "D:\soft\2019-12-03-python\lib\site-packages\flask\app.py", line 1935, in dispatch_request
    return self.view_functions[rule.endpoint](**req.view_args)
  File "D:/code/fudan/python/cpss-process/service/workflow_proxy.py", line 67, in executetask
    executor_resource_instance_id = get_resource_instance_id(executor_resource_id)
  File "D:/code/fudan/python/cpss-process/service/workflow_proxy.py", line 92, in get_resource_instance_id
    app_instance_resources = find_app_instance_resource_by_instance_id().get("resource")
  File "D:/code/fudan/python/cpss-process/service/workflow_proxy.py", line 145, in find_app_instance_resource_by_instance_id
    app_instance_resource = t_app_instance.find_one({'_id': ObjectId(workflow_instance_id)}, {"resource": 1})
  File "D:\soft\2019-12-03-python\lib\site-packages\bson\objectid.py", line 110, in __init__
    self.__validate(oid)
  File "D:\soft\2019-12-03-python\lib\site-packages\bson\objectid.py", line 213, in __validate
    _raise_invalid_id(oid)
  File "D:\soft\2019-12-03-python\lib\site-packages\bson\objectid.py", line 40, in _raise_invalid_id
    " or a 24-character hex string" % oid)
bson.errors.InvalidId: '' is not a valid ObjectId, it must be a 12-byte input or a 24-character hex string
INFO:2020-02-22 22:23:13,821:_internal.py:_log:127.0.0.1 - - [22/Feb/2020 22:23:13] "POST /run HTTP/1.1" 500 -
INFO:2020-02-22 22:23:57,334:workflow_proxy.py:init:parameters are initialized.
INFO:2020-02-22 22:23:57,337:_internal.py:_log:127.0.0.1 - - [22/Feb/2020 22:23:57] "POST /init HTTP/1.1" 200 -
INFO:2020-02-22 22:24:01,017:workflow_proxy.py:executetask:Task is run
INFO:2020-02-22 22:24:17,795:workflow_proxy.py:executetask:workflow engine is calling resource service orderCoffee
ERROR:2020-02-22 22:24:28,309:app.py:log_exception:Exception on /run [POST]
Traceback (most recent call last):
  File "D:\soft\2019-12-03-python\lib\site-packages\urllib3\connection.py", line 157, in _new_conn
    (self._dns_host, self.port), self.timeout, **extra_kw
  File "D:\soft\2019-12-03-python\lib\site-packages\urllib3\util\connection.py", line 61, in create_connection
    for res in socket.getaddrinfo(host, port, family, socket.SOCK_STREAM):
  File "D:\soft\2019-12-03-python\lib\socket.py", line 748, in getaddrinfo
    for res in _socket.getaddrinfo(host, port, family, type, proto, flags):
socket.gaierror: [Errno 11001] getaddrinfo failed

During handling of the above exception, another exception occurred:

Traceback (most recent call last):
  File "D:\soft\2019-12-03-python\lib\site-packages\urllib3\connectionpool.py", line 672, in urlopen
    chunked=chunked,
  File "D:\soft\2019-12-03-python\lib\site-packages\urllib3\connectionpool.py", line 387, in _make_request
    conn.request(method, url, **httplib_request_kw)
  File "D:\soft\2019-12-03-python\lib\http\client.py", line 1229, in request
    self._send_request(method, url, body, headers, encode_chunked)
  File "D:\soft\2019-12-03-python\lib\http\client.py", line 1275, in _send_request
    self.endheaders(body, encode_chunked=encode_chunked)
  File "D:\soft\2019-12-03-python\lib\http\client.py", line 1224, in endheaders
    self._send_output(message_body, encode_chunked=encode_chunked)
  File "D:\soft\2019-12-03-python\lib\http\client.py", line 1016, in _send_output
    self.send(msg)
  File "D:\soft\2019-12-03-python\lib\http\client.py", line 956, in send
    self.connect()
  File "D:\soft\2019-12-03-python\lib\site-packages\urllib3\connection.py", line 184, in connect
    conn = self._new_conn()
  File "D:\soft\2019-12-03-python\lib\site-packages\urllib3\connection.py", line 169, in _new_conn
    self, "Failed to establish a new connection: %s" % e
urllib3.exceptions.NewConnectionError: <urllib3.connection.HTTPConnection object at 0x000001EE27674198>: Failed to establish a new connection: [Errno 11001] getaddrinfo failed

During handling of the above exception, another exception occurred:

Traceback (most recent call last):
  File "D:\soft\2019-12-03-python\lib\site-packages\requests\adapters.py", line 449, in send
    timeout=timeout
  File "D:\soft\2019-12-03-python\lib\site-packages\urllib3\connectionpool.py", line 720, in urlopen
    method, url, error=e, _pool=self, _stacktrace=sys.exc_info()[2]
  File "D:\soft\2019-12-03-python\lib\site-packages\urllib3\util\retry.py", line 436, in increment
    raise MaxRetryError(_pool, url, error or ResponseError(cause))
urllib3.exceptions.MaxRetryError: HTTPConnectionPool(host='coffeemaker-service-proxy.default', port=8888): Max retries exceeded with url: / (Caused by NewConnectionError('<urllib3.connection.HTTPConnection object at 0x000001EE27674198>: Failed to establish a new connection: [Errno 11001] getaddrinfo failed'))

During handling of the above exception, another exception occurred:

Traceback (most recent call last):
  File "D:\soft\2019-12-03-python\lib\site-packages\flask\app.py", line 2446, in wsgi_app
    response = self.full_dispatch_request()
  File "D:\soft\2019-12-03-python\lib\site-packages\flask\app.py", line 1951, in full_dispatch_request
    rv = self.handle_user_exception(e)
  File "D:\soft\2019-12-03-python\lib\site-packages\flask\app.py", line 1820, in handle_user_exception
    reraise(exc_type, exc_value, tb)
  File "D:\soft\2019-12-03-python\lib\site-packages\flask\_compat.py", line 39, in reraise
    raise value
  File "D:\soft\2019-12-03-python\lib\site-packages\flask\app.py", line 1949, in full_dispatch_request
    rv = self.dispatch_request()
  File "D:\soft\2019-12-03-python\lib\site-packages\flask\app.py", line 1935, in dispatch_request
    return self.view_functions[rule.endpoint](**req.view_args)
  File "D:/code/fudan/python/cpss-process/service/workflow_proxy.py", line 76, in executetask
    logging.info("request result: " + requests.post(url, data).text)
  File "D:\soft\2019-12-03-python\lib\site-packages\requests\api.py", line 116, in post
    return request('post', url, data=data, json=json, **kwargs)
  File "D:\soft\2019-12-03-python\lib\site-packages\requests\api.py", line 60, in request
    return session.request(method=method, url=url, **kwargs)
  File "D:\soft\2019-12-03-python\lib\site-packages\requests\sessions.py", line 533, in request
    resp = self.send(prep, **send_kwargs)
  File "D:\soft\2019-12-03-python\lib\site-packages\requests\sessions.py", line 646, in send
    r = adapter.send(request, **kwargs)
  File "D:\soft\2019-12-03-python\lib\site-packages\requests\adapters.py", line 516, in send
    raise ConnectionError(e, request=request)
requests.exceptions.ConnectionError: HTTPConnectionPool(host='coffeemaker-service-proxy.default', port=8888): Max retries exceeded with url: / (Caused by NewConnectionError('<urllib3.connection.HTTPConnection object at 0x000001EE27674198>: Failed to establish a new connection: [Errno 11001] getaddrinfo failed'))
INFO:2020-02-22 22:24:28,455:_internal.py:_log:127.0.0.1 - - [22/Feb/2020 22:24:28] "POST /run HTTP/1.1" 500 -
INFO:2020-02-25 21:58:26,609:_internal.py:_log: * Running on http://0.0.0.0:5001/ (Press CTRL+C to quit)
INFO:2020-02-25 22:00:16,256:_internal.py:_log:127.0.0.1 - - [25/Feb/2020 22:00:16] "POST /save_app_instance_self HTTP/1.1" 404 -
INFO:2020-02-25 22:01:29,936:_internal.py:_log:127.0.0.1 - - [25/Feb/2020 22:01:29] "POST /save_app_instance_self HTTP/1.1" 404 -
INFO:2020-02-25 22:03:09,780:_internal.py:_log: * Running on http://0.0.0.0:5001/ (Press CTRL+C to quit)
INFO:2020-02-25 22:03:35,770:_internal.py:_log:127.0.0.1 - - [25/Feb/2020 22:03:35] "POST /save_app_instance_self HTTP/1.1" 404 -
INFO:2020-02-25 22:07:22,101:_internal.py:_log: * Running on http://0.0.0.0:5001/ (Press CTRL+C to quit)
INFO:2020-02-25 22:07:34,665:_internal.py:_log:127.0.0.1 - - [25/Feb/2020 22:07:34] "POST /save_app_instance_self HTTP/1.1" 404 -
INFO:2020-02-25 22:08:24,883:_internal.py:_log:127.0.0.1 - - [25/Feb/2020 22:08:24] "GET /save_app_instance_self HTTP/1.1" 404 -
